[2025-08-13T08:09:19.306+0000] {taskinstance.py:1957} INFO - Dependencies all met for dep_context=non-requeueable deps ti=<TaskInstance: weather_batch_processing.run_weather_batch_script manual__2025-08-13T08:04:11.291294+00:00 [queued]>
[2025-08-13T08:09:19.316+0000] {taskinstance.py:1957} INFO - Dependencies all met for dep_context=requeueable deps ti=<TaskInstance: weather_batch_processing.run_weather_batch_script manual__2025-08-13T08:04:11.291294+00:00 [queued]>
[2025-08-13T08:09:19.317+0000] {taskinstance.py:2171} INFO - Starting attempt 2 of 2
[2025-08-13T08:09:19.334+0000] {taskinstance.py:2192} INFO - Executing <Task(SparkSubmitOperator): run_weather_batch_script> on 2025-08-13 08:04:11.291294+00:00
[2025-08-13T08:09:19.339+0000] {standard_task_runner.py:60} INFO - Started process 331 to run task
[2025-08-13T08:09:19.344+0000] {standard_task_runner.py:87} INFO - Running: ['airflow', 'tasks', 'run', 'weather_batch_processing', 'run_weather_batch_script', 'manual__2025-08-13T08:04:11.291294+00:00', '--job-id', '3', '--raw', '--subdir', 'DAGS_FOLDER/weather_batch_dag.py', '--cfg-path', '/tmp/tmpyl687eg_']
[2025-08-13T08:09:19.347+0000] {standard_task_runner.py:88} INFO - Job 3: Subtask run_weather_batch_script
[2025-08-13T08:09:19.424+0000] {task_command.py:423} INFO - Running <TaskInstance: weather_batch_processing.run_weather_batch_script manual__2025-08-13T08:04:11.291294+00:00 [running]> on host b8abf4c23708
[2025-08-13T08:09:19.581+0000] {taskinstance.py:2481} INFO - Exporting env vars: AIRFLOW_CTX_DAG_EMAIL='your_email@example.com' AIRFLOW_CTX_DAG_OWNER='airflow' AIRFLOW_CTX_DAG_ID='weather_batch_processing' AIRFLOW_CTX_TASK_ID='run_weather_batch_script' AIRFLOW_CTX_EXECUTION_DATE='2025-08-13T08:04:11.291294+00:00' AIRFLOW_CTX_TRY_NUMBER='2' AIRFLOW_CTX_DAG_RUN_ID='manual__2025-08-13T08:04:11.291294+00:00'
[2025-08-13T08:09:19.597+0000] {base.py:83} INFO - Using connection ID 'spark_default' for task execution.
[2025-08-13T08:09:19.598+0000] {spark_submit.py:473} INFO - Spark-Submit cmd: spark-submit --master yarn --name weather_batch_job --verbose --queue root.default /home/neosoft/Desktop/wheather_analytics_trends/pyspark_jobs/process_weather_data.py
[2025-08-13T08:09:22.497+0000] {spark_submit.py:649} INFO - Using properties file: null
[2025-08-13T08:09:22.676+0000] {spark_submit.py:649} INFO - Exception in thread "main" org.apache.spark.SparkException: When running with master 'yarn' either HADOOP_CONF_DIR or YARN_CONF_DIR must be set in the environment.
[2025-08-13T08:09:22.676+0000] {spark_submit.py:649} INFO - at org.apache.spark.deploy.SparkSubmitArguments.error(SparkSubmitArguments.scala:650)
[2025-08-13T08:09:22.676+0000] {spark_submit.py:649} INFO - at org.apache.spark.deploy.SparkSubmitArguments.validateSubmitArguments(SparkSubmitArguments.scala:281)
[2025-08-13T08:09:22.677+0000] {spark_submit.py:649} INFO - at org.apache.spark.deploy.SparkSubmitArguments.validateArguments(SparkSubmitArguments.scala:237)
[2025-08-13T08:09:22.677+0000] {spark_submit.py:649} INFO - at org.apache.spark.deploy.SparkSubmitArguments.<init>(SparkSubmitArguments.scala:122)
[2025-08-13T08:09:22.677+0000] {spark_submit.py:649} INFO - at org.apache.spark.deploy.SparkSubmit$$anon$2$$anon$3.<init>(SparkSubmit.scala:1108)
[2025-08-13T08:09:22.677+0000] {spark_submit.py:649} INFO - at org.apache.spark.deploy.SparkSubmit$$anon$2.parseArguments(SparkSubmit.scala:1108)
[2025-08-13T08:09:22.677+0000] {spark_submit.py:649} INFO - at org.apache.spark.deploy.SparkSubmit.doSubmit(SparkSubmit.scala:86)
[2025-08-13T08:09:22.677+0000] {spark_submit.py:649} INFO - at org.apache.spark.deploy.SparkSubmit$$anon$2.doSubmit(SparkSubmit.scala:1125)
[2025-08-13T08:09:22.678+0000] {spark_submit.py:649} INFO - at org.apache.spark.deploy.SparkSubmit$.main(SparkSubmit.scala:1134)
[2025-08-13T08:09:22.678+0000] {spark_submit.py:649} INFO - at org.apache.spark.deploy.SparkSubmit.main(SparkSubmit.scala)
[2025-08-13T08:09:22.812+0000] {taskinstance.py:2699} ERROR - Task failed with exception
Traceback (most recent call last):
  File "/home/airflow/.local/lib/python3.8/site-packages/airflow/models/taskinstance.py", line 433, in _execute_task
    result = execute_callable(context=context, **execute_callable_kwargs)
  File "/home/airflow/.local/lib/python3.8/site-packages/airflow/providers/apache/spark/operators/spark_submit.py", line 176, in execute
    self._hook.submit(self.application)
  File "/home/airflow/.local/lib/python3.8/site-packages/airflow/providers/apache/spark/hooks/spark_submit.py", line 575, in submit
    raise AirflowException(
airflow.exceptions.AirflowException: Cannot execute: spark-submit --master yarn --name weather_batch_job --verbose --queue root.default /home/neosoft/Desktop/wheather_analytics_trends/pyspark_jobs/process_weather_data.py. Error code is: 1.
[2025-08-13T08:09:22.819+0000] {taskinstance.py:1138} INFO - Marking task as FAILED. dag_id=weather_batch_processing, task_id=run_weather_batch_script, execution_date=20250813T080411, start_date=20250813T080919, end_date=20250813T080922
[2025-08-13T08:09:22.852+0000] {logging_mixin.py:188} WARNING - /home/airflow/.local/lib/python3.8/site-packages/airflow/utils/email.py:154 RemovedInAirflow3Warning: Fetching SMTP credentials from configuration variables will be deprecated in a future release. Please set credentials using a connection instead.
[2025-08-13T08:09:22.852+0000] {configuration.py:1046} WARNING - section/key [smtp/smtp_user] not found in config
[2025-08-13T08:09:22.853+0000] {email.py:270} INFO - Email alerting: attempt 1
[2025-08-13T08:09:22.869+0000] {configuration.py:1046} WARNING - section/key [smtp/smtp_user] not found in config
[2025-08-13T08:09:22.870+0000] {email.py:270} INFO - Email alerting: attempt 1
[2025-08-13T08:09:22.870+0000] {taskinstance.py:826} ERROR - Failed to send email to: ['your_email@example.com']
Traceback (most recent call last):
  File "/home/airflow/.local/lib/python3.8/site-packages/airflow/models/taskinstance.py", line 2335, in _run_raw_task
    self._execute_task_with_callbacks(context, test_mode, session=session)
  File "/home/airflow/.local/lib/python3.8/site-packages/airflow/models/taskinstance.py", line 2500, in _execute_task_with_callbacks
    result = self._execute_task(context, task_orig)
  File "/home/airflow/.local/lib/python3.8/site-packages/airflow/models/taskinstance.py", line 2517, in _execute_task
    return _execute_task(self, context, task_orig)
  File "/home/airflow/.local/lib/python3.8/site-packages/airflow/models/taskinstance.py", line 433, in _execute_task
    result = execute_callable(context=context, **execute_callable_kwargs)
  File "/home/airflow/.local/lib/python3.8/site-packages/airflow/providers/apache/spark/operators/spark_submit.py", line 176, in execute
    self._hook.submit(self.application)
  File "/home/airflow/.local/lib/python3.8/site-packages/airflow/providers/apache/spark/hooks/spark_submit.py", line 575, in submit
    raise AirflowException(
airflow.exceptions.AirflowException: Cannot execute: spark-submit --master yarn --name weather_batch_job --verbose --queue root.default /home/neosoft/Desktop/wheather_analytics_trends/pyspark_jobs/process_weather_data.py. Error code is: 1.

During handling of the above exception, another exception occurred:

Traceback (most recent call last):
  File "/home/airflow/.local/lib/python3.8/site-packages/airflow/models/taskinstance.py", line 1000, in _email_alert
    send_email(task.email, subject, html_content)
  File "/home/airflow/.local/lib/python3.8/site-packages/airflow/utils/email.py", line 80, in send_email
    return backend(
  File "/home/airflow/.local/lib/python3.8/site-packages/airflow/utils/email.py", line 154, in send_email_smtp
    send_mime_email(e_from=mail_from, e_to=recipients, mime_msg=msg, conn_id=conn_id, dryrun=dryrun)
  File "/home/airflow/.local/lib/python3.8/site-packages/airflow/utils/email.py", line 272, in send_mime_email
    smtp_conn = _get_smtp_connection(smtp_host, smtp_port, smtp_timeout, smtp_ssl)
  File "/home/airflow/.local/lib/python3.8/site-packages/airflow/utils/email.py", line 316, in _get_smtp_connection
    return smtplib.SMTP(host=host, port=port, timeout=timeout)
  File "/usr/local/lib/python3.8/smtplib.py", line 255, in __init__
    (code, msg) = self.connect(host, port)
  File "/usr/local/lib/python3.8/smtplib.py", line 339, in connect
    self.sock = self._get_socket(host, port, self.timeout)
  File "/usr/local/lib/python3.8/smtplib.py", line 310, in _get_socket
    return socket.create_connection((host, port), timeout,
  File "/usr/local/lib/python3.8/socket.py", line 808, in create_connection
    raise err
  File "/usr/local/lib/python3.8/socket.py", line 796, in create_connection
    sock.connect(sa)
ConnectionRefusedError: [Errno 111] Connection refused

During handling of the above exception, another exception occurred:

Traceback (most recent call last):
  File "/home/airflow/.local/lib/python3.8/site-packages/airflow/models/taskinstance.py", line 824, in _handle_failure
    task_instance.email_alert(error, failure_context["task"])
  File "/home/airflow/.local/lib/python3.8/site-packages/airflow/models/taskinstance.py", line 2947, in email_alert
    _email_alert(task_instance=self, exception=exception, task=task)
  File "/home/airflow/.local/lib/python3.8/site-packages/airflow/models/taskinstance.py", line 1002, in _email_alert
    send_email(task.email, subject, html_content_err)
  File "/home/airflow/.local/lib/python3.8/site-packages/airflow/utils/email.py", line 80, in send_email
    return backend(
  File "/home/airflow/.local/lib/python3.8/site-packages/airflow/utils/email.py", line 154, in send_email_smtp
    send_mime_email(e_from=mail_from, e_to=recipients, mime_msg=msg, conn_id=conn_id, dryrun=dryrun)
  File "/home/airflow/.local/lib/python3.8/site-packages/airflow/utils/email.py", line 272, in send_mime_email
    smtp_conn = _get_smtp_connection(smtp_host, smtp_port, smtp_timeout, smtp_ssl)
  File "/home/airflow/.local/lib/python3.8/site-packages/airflow/utils/email.py", line 316, in _get_smtp_connection
    return smtplib.SMTP(host=host, port=port, timeout=timeout)
  File "/usr/local/lib/python3.8/smtplib.py", line 255, in __init__
    (code, msg) = self.connect(host, port)
  File "/usr/local/lib/python3.8/smtplib.py", line 339, in connect
    self.sock = self._get_socket(host, port, self.timeout)
  File "/usr/local/lib/python3.8/smtplib.py", line 310, in _get_socket
    return socket.create_connection((host, port), timeout,
  File "/usr/local/lib/python3.8/socket.py", line 808, in create_connection
    raise err
  File "/usr/local/lib/python3.8/socket.py", line 796, in create_connection
    sock.connect(sa)
ConnectionRefusedError: [Errno 111] Connection refused
[2025-08-13T08:09:22.904+0000] {standard_task_runner.py:107} ERROR - Failed to execute job 3 for task run_weather_batch_script (Cannot execute: spark-submit --master yarn --name weather_batch_job --verbose --queue root.default /home/neosoft/Desktop/wheather_analytics_trends/pyspark_jobs/process_weather_data.py. Error code is: 1.; 331)
[2025-08-13T08:09:22.930+0000] {local_task_job_runner.py:234} INFO - Task exited with return code 1
[2025-08-13T08:09:22.966+0000] {taskinstance.py:3281} INFO - 0 downstream tasks scheduled from follow-on schedule check
